INFO:root:Loop starting
INFO:root:Closing loop...
INFO:root:Loop closed
INFO:root:Loop starting
INFO:root:Loop starting
INFO:root:Closing loop...
INFO:root:Loop closed
ERROR:asyncio:Task exception was never retrieved
future: <Task finished name='Task-1' coro=<main() done, defined at /home/sinister/listener_practice/one/Sferum_distribution_of_messages/main.py:14> exception=InvalidURL("Invalid URL 'http:localhost:9001/post.php': No host supplied")>
Traceback (most recent call last):
  File "/home/sinister/listener_practice/one/Sferum_distribution_of_messages/main.py", line 25, in main
    PostResponse("http:localhost:9001/post.php", {"name": text})
  File "/home/sinister/listener_practice/one/Sferum_distribution_of_messages/main.py", line 10, in PostResponse
    response = requests.post(url, data)
               ^^^^^^^^^^^^^^^^^^^^^^^^
  File "/home/sinister/.local/share/virtualenvs/Sferum_distribution_of_messages-UJUTvUTI/lib/python3.11/site-packages/requests/api.py", line 115, in post
    return request("post", url, data=data, json=json, **kwargs)
           ^^^^^^^^^^^^^^^^^^^^^^^^^^^^^^^^^^^^^^^^^^^^^^^^^^^^
  File "/home/sinister/.local/share/virtualenvs/Sferum_distribution_of_messages-UJUTvUTI/lib/python3.11/site-packages/requests/api.py", line 59, in request
    return session.request(method=method, url=url, **kwargs)
           ^^^^^^^^^^^^^^^^^^^^^^^^^^^^^^^^^^^^^^^^^^^^^^^^^
  File "/home/sinister/.local/share/virtualenvs/Sferum_distribution_of_messages-UJUTvUTI/lib/python3.11/site-packages/requests/sessions.py", line 575, in request
    prep = self.prepare_request(req)
           ^^^^^^^^^^^^^^^^^^^^^^^^^
  File "/home/sinister/.local/share/virtualenvs/Sferum_distribution_of_messages-UJUTvUTI/lib/python3.11/site-packages/requests/sessions.py", line 484, in prepare_request
    p.prepare(
  File "/home/sinister/.local/share/virtualenvs/Sferum_distribution_of_messages-UJUTvUTI/lib/python3.11/site-packages/requests/models.py", line 367, in prepare
    self.prepare_url(url, params)
  File "/home/sinister/.local/share/virtualenvs/Sferum_distribution_of_messages-UJUTvUTI/lib/python3.11/site-packages/requests/models.py", line 444, in prepare_url
    raise InvalidURL(f"Invalid URL {url!r}: No host supplied")
requests.exceptions.InvalidURL: Invalid URL 'http:localhost:9001/post.php': No host supplied
INFO:root:Loop starting
INFO:root:Closing loop...
INFO:root:Loop closed
ERROR:asyncio:Task exception was never retrieved
future: <Task finished name='Task-1' coro=<main() done, defined at /home/sinister/listener_practice/one/Sferum_distribution_of_messages/main.py:14> exception=InvalidURL("Invalid URL 'http:localhost:9001/post.php': No host supplied")>
Traceback (most recent call last):
  File "/home/sinister/listener_practice/one/Sferum_distribution_of_messages/main.py", line 25, in main
    result = await PostResponse("http:localhost:9001/post.php", {"name": text})
             ^^^^^^^^^^^^^^^^^^^^^^^^^^^^^^^^^^^^^^^^^^^^^^^^^^^^^^^^^^^^^^^^^^
  File "/home/sinister/listener_practice/one/Sferum_distribution_of_messages/main.py", line 10, in PostResponse
    response = await requests.post(url, data)
                     ^^^^^^^^^^^^^^^^^^^^^^^^
  File "/home/sinister/.local/share/virtualenvs/Sferum_distribution_of_messages-UJUTvUTI/lib/python3.11/site-packages/requests/api.py", line 115, in post
    return request("post", url, data=data, json=json, **kwargs)
           ^^^^^^^^^^^^^^^^^^^^^^^^^^^^^^^^^^^^^^^^^^^^^^^^^^^^
  File "/home/sinister/.local/share/virtualenvs/Sferum_distribution_of_messages-UJUTvUTI/lib/python3.11/site-packages/requests/api.py", line 59, in request
    return session.request(method=method, url=url, **kwargs)
           ^^^^^^^^^^^^^^^^^^^^^^^^^^^^^^^^^^^^^^^^^^^^^^^^^
  File "/home/sinister/.local/share/virtualenvs/Sferum_distribution_of_messages-UJUTvUTI/lib/python3.11/site-packages/requests/sessions.py", line 575, in request
    prep = self.prepare_request(req)
           ^^^^^^^^^^^^^^^^^^^^^^^^^
  File "/home/sinister/.local/share/virtualenvs/Sferum_distribution_of_messages-UJUTvUTI/lib/python3.11/site-packages/requests/sessions.py", line 484, in prepare_request
    p.prepare(
  File "/home/sinister/.local/share/virtualenvs/Sferum_distribution_of_messages-UJUTvUTI/lib/python3.11/site-packages/requests/models.py", line 367, in prepare
    self.prepare_url(url, params)
  File "/home/sinister/.local/share/virtualenvs/Sferum_distribution_of_messages-UJUTvUTI/lib/python3.11/site-packages/requests/models.py", line 444, in prepare_url
    raise InvalidURL(f"Invalid URL {url!r}: No host supplied")
requests.exceptions.InvalidURL: Invalid URL 'http:localhost:9001/post.php': No host supplied
INFO:root:Loop starting
INFO:root:Closing loop...
INFO:root:Loop closed
ERROR:asyncio:Task exception was never retrieved
future: <Task finished name='Task-1' coro=<main() done, defined at /home/sinister/listener_practice/one/Sferum_distribution_of_messages/main.py:14> exception=InvalidURL("Invalid URL 'http:localhost:9001/post.php': No host supplied")>
Traceback (most recent call last):
  File "/home/sinister/listener_practice/one/Sferum_distribution_of_messages/main.py", line 25, in main
    result = await PostResponse("http:localhost:9001/post.php", {"name": text})
             ^^^^^^^^^^^^^^^^^^^^^^^^^^^^^^^^^^^^^^^^^^^^^^^^^^^^^^^^^^^^^^^^^^
  File "/home/sinister/listener_practice/one/Sferum_distribution_of_messages/main.py", line 10, in PostResponse
    response = await requests.post(url, data)
                     ^^^^^^^^^^^^^^^^^^^^^^^^
  File "/home/sinister/.local/share/virtualenvs/Sferum_distribution_of_messages-UJUTvUTI/lib/python3.11/site-packages/requests/api.py", line 115, in post
    return request("post", url, data=data, json=json, **kwargs)
           ^^^^^^^^^^^^^^^^^^^^^^^^^^^^^^^^^^^^^^^^^^^^^^^^^^^^
  File "/home/sinister/.local/share/virtualenvs/Sferum_distribution_of_messages-UJUTvUTI/lib/python3.11/site-packages/requests/api.py", line 59, in request
    return session.request(method=method, url=url, **kwargs)
           ^^^^^^^^^^^^^^^^^^^^^^^^^^^^^^^^^^^^^^^^^^^^^^^^^
  File "/home/sinister/.local/share/virtualenvs/Sferum_distribution_of_messages-UJUTvUTI/lib/python3.11/site-packages/requests/sessions.py", line 575, in request
    prep = self.prepare_request(req)
           ^^^^^^^^^^^^^^^^^^^^^^^^^
  File "/home/sinister/.local/share/virtualenvs/Sferum_distribution_of_messages-UJUTvUTI/lib/python3.11/site-packages/requests/sessions.py", line 484, in prepare_request
    p.prepare(
  File "/home/sinister/.local/share/virtualenvs/Sferum_distribution_of_messages-UJUTvUTI/lib/python3.11/site-packages/requests/models.py", line 367, in prepare
    self.prepare_url(url, params)
  File "/home/sinister/.local/share/virtualenvs/Sferum_distribution_of_messages-UJUTvUTI/lib/python3.11/site-packages/requests/models.py", line 444, in prepare_url
    raise InvalidURL(f"Invalid URL {url!r}: No host supplied")
requests.exceptions.InvalidURL: Invalid URL 'http:localhost:9001/post.php': No host supplied
INFO:root:Loop starting
INFO:root:Closing loop...
INFO:root:Loop closed
ERROR:asyncio:Task exception was never retrieved
future: <Task finished name='Task-1' coro=<main() done, defined at /home/sinister/listener_practice/one/Sferum_distribution_of_messages/main.py:14> exception=InvalidURL("Invalid URL 'http:localhost:9001/post.php': No host supplied")>
Traceback (most recent call last):
  File "/home/sinister/listener_practice/one/Sferum_distribution_of_messages/main.py", line 25, in main
    result = await PostResponse("http://localhost:9001/post.php", {"name": text})
             ^^^^^^^^^^^^^^^^^^^^^^^^^^^^^^^^^^^^^^^^^^^^^^^^^^^^^^^^^^^^^^^^^^
  File "/home/sinister/listener_practice/one/Sferum_distribution_of_messages/main.py", line 10, in PostResponse
    response = await requests.post(url, data)
                     ^^^^^^^^^^^^^^^^^^^^^^^^
  File "/home/sinister/.local/share/virtualenvs/Sferum_distribution_of_messages-UJUTvUTI/lib/python3.11/site-packages/requests/api.py", line 115, in post
    return request("post", url, data=data, json=json, **kwargs)
           ^^^^^^^^^^^^^^^^^^^^^^^^^^^^^^^^^^^^^^^^^^^^^^^^^^^^
  File "/home/sinister/.local/share/virtualenvs/Sferum_distribution_of_messages-UJUTvUTI/lib/python3.11/site-packages/requests/api.py", line 59, in request
    return session.request(method=method, url=url, **kwargs)
           ^^^^^^^^^^^^^^^^^^^^^^^^^^^^^^^^^^^^^^^^^^^^^^^^^
  File "/home/sinister/.local/share/virtualenvs/Sferum_distribution_of_messages-UJUTvUTI/lib/python3.11/site-packages/requests/sessions.py", line 575, in request
    prep = self.prepare_request(req)
           ^^^^^^^^^^^^^^^^^^^^^^^^^
  File "/home/sinister/.local/share/virtualenvs/Sferum_distribution_of_messages-UJUTvUTI/lib/python3.11/site-packages/requests/sessions.py", line 484, in prepare_request
    p.prepare(
  File "/home/sinister/.local/share/virtualenvs/Sferum_distribution_of_messages-UJUTvUTI/lib/python3.11/site-packages/requests/models.py", line 367, in prepare
    self.prepare_url(url, params)
  File "/home/sinister/.local/share/virtualenvs/Sferum_distribution_of_messages-UJUTvUTI/lib/python3.11/site-packages/requests/models.py", line 444, in prepare_url
    raise InvalidURL(f"Invalid URL {url!r}: No host supplied")
requests.exceptions.InvalidURL: Invalid URL 'http:localhost:9001/post.php': No host supplied
INFO:root:Loop starting
INFO:root:Closing loop...
INFO:root:Loop closed
ERROR:asyncio:Task exception was never retrieved
future: <Task finished name='Task-1' coro=<main() done, defined at /home/sinister/listener_practice/one/Sferum_distribution_of_messages/main.py:14> exception=TypeError("object Response can't be used in 'await' expression")>
Traceback (most recent call last):
  File "/home/sinister/listener_practice/one/Sferum_distribution_of_messages/main.py", line 25, in main
    result = await PostResponse("http://localhost:9001/post.php", {"name": text})
             ^^^^^^^^^^^^^^^^^^^^^^^^^^^^^^^^^^^^^^^^^^^^^^^^^^^^^^^^^^^^^^^^^^^^
  File "/home/sinister/listener_practice/one/Sferum_distribution_of_messages/main.py", line 10, in PostResponse
    response = await requests.post(url, data)
               ^^^^^^^^^^^^^^^^^^^^^^^^^^^^^^
TypeError: object Response can't be used in 'await' expression
INFO:root:Loop starting
INFO:root:Closing loop...
INFO:root:Loop closed
ERROR:asyncio:Task exception was never retrieved
future: <Task finished name='Task-1' coro=<main() done, defined at /home/sinister/listener_practice/one/Sferum_distribution_of_messages/main.py:14> exception=TypeError("object Response can't be used in 'await' expression")>
Traceback (most recent call last):
  File "/home/sinister/listener_practice/one/Sferum_distribution_of_messages/main.py", line 25, in main
    result = await PostResponse("http://localhost:9001/post.php", {"name": text})
             ^^^^^^^^^^^^^^^^^^^^^^^^^^^^^^^^^^^^^^^^^^^^^^^^^^^^^^^^^^^^^^^^^^^^
  File "/home/sinister/listener_practice/one/Sferum_distribution_of_messages/main.py", line 10, in PostResponse
    response = await requests.post(url, data)
               ^^^^^^^^^^^^^^^^^^^^^^^^^^^^^^
TypeError: object Response can't be used in 'await' expression
INFO:root:Loop starting
INFO:root:Closing loop...
INFO:root:Loop closed
ERROR:asyncio:Task exception was never retrieved
future: <Task finished name='Task-1' coro=<main() done, defined at /home/sinister/listener_practice/one/Sferum_distribution_of_messages/main.py:14> exception=TypeError("object Response can't be used in 'await' expression")>
Traceback (most recent call last):
  File "/home/sinister/listener_practice/one/Sferum_distribution_of_messages/main.py", line 25, in main
    print("Результат отправки POST запроса: ", result)
            ^^^^^^^^^^^^^^^^^^^^^^^^^^^^^^^^^^^^^^^^^^^
  File "/home/sinister/listener_practice/one/Sferum_distribution_of_messages/main.py", line 10, in PostResponse
    return response.status_code
               ^^^^^^^^^^^^^^^^^
TypeError: object Response can't be used in 'await' expression
INFO:root:Loop starting
INFO:root:Closing loop...
INFO:root:Loop closed
ERROR:asyncio:Task exception was never retrieved
future: <Task finished name='Task-1' coro=<main() done, defined at /home/sinister/listener_practice/one/Sferum_distribution_of_messages/main.py:13> exception=SystemExit(0)>
Traceback (most recent call last):
  File "/home/sinister/listener_practice/one/Sferum_distribution_of_messages/startup.py", line 48, in <module>
    loop.run_forever()
  File "/usr/lib/python3.11/asyncio/base_events.py", line 607, in run_forever
    self._run_once()
  File "/usr/lib/python3.11/asyncio/base_events.py", line 1922, in _run_once
    handle._run()
  File "/usr/lib/python3.11/asyncio/events.py", line 80, in _run
    self._context.run(self._callback, *self._args)
  File "/home/sinister/listener_practice/one/Sferum_distribution_of_messages/main.py", line 26, in main
    exit(0)
  File "<frozen _sitebuiltins>", line 26, in __call__
SystemExit: 0
INFO:root:Loop starting
INFO:root:Closing loop...
INFO:root:Loop closed
ERROR:asyncio:Task exception was never retrieved
future: <Task finished name='Task-1' coro=<main() done, defined at /home/sinister/listener_practice/one/Sferum_distribution_of_messages/main.py:13> exception=SystemExit(0)>
Traceback (most recent call last):
  File "/home/sinister/listener_practice/one/Sferum_distribution_of_messages/startup.py", line 48, in <module>
    loop.run_forever()
  File "/usr/lib/python3.11/asyncio/base_events.py", line 607, in run_forever
    self._run_once()
  File "/usr/lib/python3.11/asyncio/base_events.py", line 1922, in _run_once
    handle._run()
  File "/usr/lib/python3.11/asyncio/events.py", line 80, in _run
    self._context.run(self._callback, *self._args)
  File "/home/sinister/listener_practice/one/Sferum_distribution_of_messages/main.py", line 26, in main
    exit(0)
  File "<frozen _sitebuiltins>", line 26, in __call__
SystemExit: 0
INFO:root:Loop starting
INFO:root:Closing loop...
INFO:root:Loop closed
ERROR:asyncio:Task exception was never retrieved
future: <Task finished name='Task-1' coro=<main() done, defined at /home/sinister/listener_practice/one/Sferum_distribution_of_messages/main.py:13> exception=SystemExit(0)>
Traceback (most recent call last):
  File "/home/sinister/listener_practice/one/Sferum_distribution_of_messages/startup.py", line 48, in <module>
    loop.run_forever()
  File "/usr/lib/python3.11/asyncio/base_events.py", line 607, in run_forever
    self._run_once()
  File "/usr/lib/python3.11/asyncio/base_events.py", line 1922, in _run_once
    handle._run()
  File "/usr/lib/python3.11/asyncio/events.py", line 80, in _run
    self._context.run(self._callback, *self._args)
  File "/home/sinister/listener_practice/one/Sferum_distribution_of_messages/main.py", line 26, in main
    exit(0)
  File "<frozen _sitebuiltins>", line 26, in __call__
SystemExit: 0
INFO:root:Loop starting
INFO:root:Closing loop...
INFO:root:Loop closed
ERROR:asyncio:Task exception was never retrieved
future: <Task finished name='Task-1' coro=<main() done, defined at /home/sinister/listener_practice/one/Sferum_distribution_of_messages/main.py:13> exception=SystemExit(0)>
Traceback (most recent call last):
  File "/home/sinister/listener_practice/one/Sferum_distribution_of_messages/startup.py", line 48, in <module>
    loop.run_forever()
  File "/usr/lib/python3.11/asyncio/base_events.py", line 607, in run_forever
    self._run_once()
  File "/usr/lib/python3.11/asyncio/base_events.py", line 1922, in _run_once
    handle._run()
  File "/usr/lib/python3.11/asyncio/events.py", line 80, in _run
    self._context.run(self._callback, *self._args)
  File "/home/sinister/listener_practice/one/Sferum_distribution_of_messages/main.py", line 26, in main
    exit(0)
  File "<frozen _sitebuiltins>", line 26, in __call__
SystemExit: 0
INFO:root:Loop starting
INFO:root:Closing loop...
INFO:root:Loop closed
ERROR:asyncio:Task exception was never retrieved
future: <Task finished name='Task-1' coro=<main() done, defined at /home/sinister/listener_practice/one/Sferum_distribution_of_messages/main.py:13> exception=SystemExit(0)>
Traceback (most recent call last):
  File "/home/sinister/listener_practice/one/Sferum_distribution_of_messages/startup.py", line 48, in <module>
    loop.run_forever()
  File "/usr/lib/python3.11/asyncio/base_events.py", line 607, in run_forever
    self._run_once()
  File "/usr/lib/python3.11/asyncio/base_events.py", line 1922, in _run_once
    handle._run()
  File "/usr/lib/python3.11/asyncio/events.py", line 80, in _run
    self._context.run(self._callback, *self._args)
  File "/home/sinister/listener_practice/one/Sferum_distribution_of_messages/main.py", line 26, in main
    exit(0)
  File "<frozen _sitebuiltins>", line 26, in __call__
SystemExit: 0
INFO:root:Loop starting
INFO:root:Closing loop...
INFO:root:Loop closed
ERROR:asyncio:Task exception was never retrieved
future: <Task finished name='Task-1' coro=<main() done, defined at /home/sinister/listener_practice/one/Sferum_distribution_of_messages/main.py:13> exception=SystemExit(0)>
Traceback (most recent call last):
  File "/home/sinister/listener_practice/one/Sferum_distribution_of_messages/startup.py", line 48, in <module>
    loop.run_forever()
  File "/usr/lib/python3.11/asyncio/base_events.py", line 607, in run_forever
    self._run_once()
  File "/usr/lib/python3.11/asyncio/base_events.py", line 1922, in _run_once
    handle._run()
  File "/usr/lib/python3.11/asyncio/events.py", line 80, in _run
    self._context.run(self._callback, *self._args)
  File "/home/sinister/listener_practice/one/Sferum_distribution_of_messages/main.py", line 26, in main
    exit(0)
  File "<frozen _sitebuiltins>", line 26, in __call__
SystemExit: 0
INFO:root:Loop starting
